Workbook

Sheet Overview
B5: Overview | D5: Total Patients | E5: Diagnosis Positive | F5: Diagnosis Rate | G5: Avg BMI | H5: Avg Symptom Count | I5: Smoking Rate
B6: Dash 1
B7: Dash 2 | D7: =Calc!B2 -> 2392 | E7: =Calc!B3 -> 1171 | F7: =Calc!B4 -> 0.48954849 | G7: =Calc!B5 -> 26.131961 | H7: =Calc!B6 -> 2.3858696 | I7: =Calc!B7 -> 0.19983278
B9: Gender
B10: All
B11: Ethnicity
B12: All
B13: Smoking
B14: All
B15: Age Group
B16: All
B17: BMI Category
B18: All

Sheet Dash 1
D1: Patient Level Analysis
B5: Overview
B6: Dash 1
B7: Dash 2
B9: Gender
B10: All
B11: Ethnicity
B12: All
B13: Smoking
B14: All
B15: Age Group
B16: All
B17: BMI Category
B18: All

Sheet Dash 2
D1: Patient Level Analysis
B5: Overview
B6: Dash 1
B7: Dash 2
B9: Gender
B10: All
B11: Ethnicity
B12: All
B13: Smoking
B14: All
B15: Age Group
B16: All
B17: BMI Category
B18: All

Sheet Data
A1: PatientID | B1: Age | C1: Gender | D1: Ethnicity | E1: EducationLevel | F1: BMI | G1: Smoking | H1: PhysicalActivity | I1: DietQuality | J1: SleepQuality | K1: PollutionExposure | L1: PollenExposure | M1: DustExposure | N1: PetAllergy | O1: FamilyHistoryAsthma | P1: HistoryOfAllergies | Q1: Eczema | R1: HayFever | S1: GastroesophagealReflux | T1: LungFunctionFEV1 | U1: LungFunctionFVC | V1: Wheezing | W1: ShortnessOfBreath | X1: ChestTightness | Y1: Coughing | Z1: NighttimeSymptoms | AA1: ExerciseInduced | AB1: Diagnosis | AC1: Gender_Label | AD1: Ethnicity_Label | AE1: EducationLevel_Label | AF1: Smoking_Label | AG1: PetAllergy_Label | AH1: FamilyHistoryAsthma_Label | AI1: HistoryOfAllergies_Label | AJ1: Eczema_Label | AK1: HayFever_Label | AL1: GastroesophagealReflux_Label | AM1: Wheezing_Label | AN1: ShortnessOfBreath_Label | AO1: ChestTightness_Label | AP1: Coughing_Label | AQ1: NighttimeSymptoms_Label | AR1: ExerciseInduced_Label | AS1: Diagnosis_Label | AT1: AgeGroup | AU1: BMICategory | AV1: FEV1_FVC_Ratio | AW1: SymptomCount | AX1: RiskFactorCount | AY1: MatchFilter_Overview | AZ1: MatchFilter_Dash1 | BA1: MatchFilter_Dash2
A2: 5034 | B2: 11 | C2: 1 | D2: 0 | E2: 3 | F2: 24.09 | G2: 0 | H2: 0.99 | I2: 3.03 | J2: 4.35 | K2: 4.57 | L2: 6.85 | M2: 6.06 | N2: 1 | O2: 1 | P2: 0 | Q2: 0 | R2: 1 | S2: 0 | T2: 2.48 | U2: 3.3 | V2: 0 | W2: 1 | X2: 1 | Y2: 1 | Z2: 1 | AA2: 1 | AB2: 1 | AC2: Female | AD2: Caucasian | AE2: Higher | AF2: No | AG2: Yes | AH2: Yes | AI2: No | AJ2: No | AK2: Yes | AL2: No | AM2: No | AN2: Yes | AO2: Yes | AP2: Yes | AQ2: Yes | AR2: Yes | AS2: Positive | AT2: 0-17 (Child) | AU2: Normal | AV2: 0.75 | AW2: 5 | AX2: 2 | AY2: =IF(AND(OR(Overview!$B$10="All",AC2=Overview!$B$10),OR(Overview!$B$12="All",AD2=Overview!$B$12),OR(Overview!$B$14="All",AF2=Overview!$B$14),OR(Overview!$B$16="All",AT2=Overview!$B$16),OR(Overview!$B$18="All",AU2=Overview!$B$18)),1,0) -> 1 | AZ2: =IF(AND(OR('Dash 1'!$B$10="All",AC2='Dash 1'!$B$10),OR('Dash 1'!$B$12="All",AD2='Dash 1'!$B$12),OR('Dash 1'!$B$14="All",AF2='Dash 1'!$B$14),OR('Dash 1'!$B$16="All",AT2='Dash 1'!$B$16),OR('Dash 1'!$B$18="All",AU2='Dash 1'!$B$18)),1,0) -> 1 | BA2: =IF(AND(OR('Dash 2'!$B$10="All",AC2='Dash 2'!$B$10),OR('Dash 2'!$B$12="All",AD2='Dash 2'!$B$12),OR('Dash 2'!$B$14="All",AF2='Dash 2'!$B$14),OR('Dash 2'!$B$16="All",AT2='Dash 2'!$B$16),OR('Dash 2'!$B$18="All",AU2='Dash 2'!$B$18)),1,0) -> 1
A3: 5035 | B3: 63 | C3: 0 | D3: 0 | E3: 3 | F3: 27.73 | G3: 1 | H3: 4.44 | I3: 6.89 | J3: 6.22 | K3: 4.45 | L3: 3.96 | M3: 7.25 | N3: 0 | O3: 0 | P3: 1 | Q3: 0 | R3: 0 | S3: 0 | T3: 2.03 | U3: 2.62 | V3: 1 | W3: 1 | X3: 0 | Y3: 1 | Z3: 1 | AA3: 0 | AB3: 1 | AC3: Male | AD3: Caucasian | AE3: Higher | AF3: Yes | AG3: No | AH3: No | AI3: Yes | AJ3: No | AK3: No | AL3: No | AM3: Yes | AN3: Yes | AO3: No | AP3: Yes | AQ3: Yes | AR3: No | AS3: Positive | AT3: 60+ | AU3: Overweight | AV3: 0.78 | AW3: 4 | AX3: 1 | AY3: =IF(AND(OR(Overview!$B$10="All",AC3=Overview!$B$10),OR(Overview!$B$12="All",AD3=Overview!$B$12),OR(Overview!$B$14="All",AF3=Overview!$B$14),OR(Overview!$B$16="All",AT3=Overview!$B$16),OR(Overview!$B$18="All",AU3=Overview!$B$18)),1,0) -> 1 | AZ3: =IF(AND(OR('Dash 1'!$B$10="All",AC3='Dash 1'!$B$10),OR('Dash 1'!$B$12="All",AD3='Dash 1'!$B$12),OR('Dash 1'!$B$14="All",AF3='Dash 1'!$B$14),OR('Dash 1'!$B$16="All",AT3='Dash 1'!$B$16),OR('Dash 1'!$B$18="All",AU3='Dash 1'!$B$18)),1,0) -> 1 | BA3: =IF(AND(OR('Dash 2'!$B$10="All",AC3='Dash 2'!$B$10),OR('Dash 2'!$B$12="All",AD3='Dash 2'!$B$12),OR('Dash 2'!$B$14="All",AF3='Dash 2'!$B$14),OR('Dash 2'!$B$16="All",AT3='Dash 2'!$B$16),OR('Dash 2'!$B$18="All",AU3='Dash 2'!$B$18)),1,0) -> 1
A4: 5036 | B4: 54 | C4: 0 | D4: 1 | E4: 1 | F4: 21.87 | G4: 1 | H4: 0.4 | I4: 3.59 | J4: 7.64 | K4: 6.27 | L4: 4.07 | M4: 7.18 | N4: 0 | O4: 0 | P4: 1 | Q4: 0 | R4: 1 | S4: 1 | T4: 2.04 | U4: 2.9 | V4: 0 | W4: 1 | X4: 1 | Y4: 0 | Z4: 1 | AA4: 0 | AB4: 1 | AC4: Male | AD4: African American | AE4: High School | AF4: Yes | AG4: No | AH4: No | AI4: Yes | AJ4: No | AK4: Yes | AL4: Yes | AM4: No | AN4: Yes | AO4: Yes | AP4: No | AQ4: Yes | AR4: No | AS4: Positive | AT4: 45-59 | AU4: Normal | AV4: 0.7 | AW4: 3 | AX4: 3 | AY4: =IF(AND(OR(Overview!$B$10="All",AC4=Overview!$B$10),OR(Overview!$B$12="All",AD4=Overview!$B$12),OR(Overview!$B$14="All",AF4=Overview!$B$14),OR(Overview!$B$16="All",AT4=Overview!$B$16),OR(Overview!$B$18="All",AU4=Overview!$B$18)),1,0) -> 1 | AZ4: =IF(AND(OR('Dash 1'!$B$10="All",AC4='Dash 1'!$B$10),OR('Dash 1'!$B$12="All",AD4='Dash 1'!$B$12),OR('Dash 1'!$B$14="All",AF4='Dash 1'!$B$14),OR('Dash 1'!$B$16="All",AT4='Dash 1'!$B$16),OR('Dash 1'!$B$18="All",AU4='Dash 1'!$B$18)),1,0) -> 1 | BA4: =IF(AND(OR('Dash 2'!$B$10="All",AC4='Dash 2'!$B$10),OR('Dash 2'!$B$12="All",AD4='Dash 2'!$B$12),OR('Dash 2'!$B$14="All",AF4='Dash 2'!$B$14),OR('Dash 2'!$B$16="All",AT4='Dash 2'!$B$16),OR('Dash 2'!$B$18="All",AU4='Dash 2'!$B$18)),1,0) -> 1
A5: 5037 | B5: 38 | C5: 1 | D5: 3 | E5: 2 | F5: 23.82 | G5: 0 | H5: 1.42 | I5: 3.66 | J5: 5.9 | K5: 6.59 | L5: 6.97 | M5: 1.8 | N5: 0 | O5: 0 | P5: 1 | Q5: 0 | R5: 0 | S5: 1 | T5: 3.33 | U5: 3.7 | V5: 0 | W5: 0 | X5: 0 | Y5: 0 | Z5: 0 | AA5: 0 | AB5: 0 | AC5: Female | AD5: Other | AE5: Bachelor's | AF5: No | AG5: No | AH5: No | AI5: Yes | AJ5: No | AK5: No | AL5: Yes | AM5: No | AN5: No | AO5: No | AP5: No | AQ5: No | AR5: No | AS5: Negative | AT5: 30-44 | AU5: Normal | AV5: 0.9 | AW5: 0 | AX5: 2 | AY5: =IF(AND(OR(Overview!$B$10="All",AC5=Overview!$B$10),OR(Overview!$B$12="All",AD5=Overview!$B$12),OR(Overview!$B$14="All",AF5=Overview!$B$14),OR(Overview!$B$16="All",AT5=Overview!$B$16),OR(Overview!$B$18="All",AU5=Overview!$B$18)),1,0) -> 1 | AZ5: =IF(AND(OR('Dash 1'!$B$10="All",AC5='Dash 1'!$B$10),OR('Dash 1'!$B$12="All",AD5='Dash 1'!$B$12),OR('Dash 1'!$B$14="All",AF5='Dash 1'!$B$14),OR('Dash 1'!$B$16="All",AT5='Dash 1'!$B$16),OR('Dash 1'!$B$18="All",AU5='Dash 1'!$B$18)),1,0) -> 1 | BA5: =IF(AND(OR('Dash 2'!$B$10="All",AC5='Dash 2'!$B$10),OR('Dash 2'!$B$12="All",AD5='Dash 2'!$B$12),OR('Dash 2'!$B$14="All",AF5='Dash 2'!$B$14),OR('Dash 2'!$B$16="All",AT5='Dash 2'!$B$16),OR('Dash 2'!$B$18="All",AU5='Dash 2'!$B$18)),1,0) -> 1
A6: 5038 | B6: 37 | C6: 1 | D6: 0 | E6: 1 | F6: 24.4 | G6: 0 | H6: 5.42 | I6: 7.11 | J6: 6.69 | K6: 6.29 | L6: 5.51 | M6: 6.75 | N6: 0 | O6: 0 | P6: 0 | Q6: 0 | R6: 0 | S6: 0 | T6: 2.38 | U6: 2.95 | V6: 1 | W6: 1 | X6: 1 | Y6: 0 | Z6: 0 | AA6: 1 | AB6: 1 | AC6: Female | AD6: Caucasian | AE6: High School | AF6: No | AG6: No | AH6: No | AI6: No | AJ6: No | AK6: No | AL6: No | AM6: Yes | AN6: Yes | AO6: Yes | AP6: No | AQ6: No | AR6: Yes | AS6: Positive | AT6: 30-44 | AU6: Normal | AV6: 0.81 | AW6: 4 | AX6: 0 | AY6: =IF(AND(OR(Overview!$B$10="All",AC6=Overview!$B$10),OR(Overview!$B$12="All",AD6=Overview!$B$12),OR(Overview!$B$14="All",AF6=Overview!$B$14),OR(Overview!$B$16="All",AT6=Overview!$B$16),OR(Overview!$B$18="All",AU6=Overview!$B$18)),1,0) -> 1 | AZ6: =IF(AND(OR('Dash 1'!$B$10="All",AC6='Dash 1'!$B$10),OR('Dash 1'!$B$12="All",AD6='Dash 1'!$B$12),OR('Dash 1'!$B$14="All",AF6='Dash 1'!$B$14),OR('Dash 1'!$B$16="All",AT6='Dash 1'!$B$16),OR('Dash 1'!$B$18="All",AU6='Dash 1'!$B$18)),1,0) -> 1 | BA6: =IF(AND(OR('Dash 2'!$B$10="All",AC6='Dash 2'!$B$10),OR('Dash 2'!$B$12="All",AD6='Dash 2'!$B$12),OR('Dash 2'!$B$14="All",AF6='Dash 2'!$B$14),OR('Dash 2'!$B$16="All",AT6='Dash 2'!$B$16),OR('Dash 2'!$B$18="All",AU6='Dash 2'!$B$18)),1,0) -> 1
A7: 5039 | B7: 70 | C7: 0 | D7: 0 | E7: 2 | F7: 19.77 | G7: 0 | H7: 2.55 | I7: 5.91 | J7: 7.77 | K7: 5.85 | L7: 2.2 | M7: 2.45 | N7: 0 | O7: 0 | P7: 0 | Q7: 0 | R7: 0 | S7: 0 | T7: 2.77 | U7: 3.13 | V7: 0 | W7: 1 | X7: 1 | Y7: 0 | Z7: 1 | AA7: 1 | AB7: 1 | AC7: Male | AD7: Caucasian | AE7: Bachelor's | AF7: No | AG7: No | AH7: No | AI7: No | AJ7: No | AK7: No | AL7: No | AM7: No | AN7: Yes | AO7: Yes | AP7: No | AQ7: Yes | AR7: Yes | AS7: Positive | AT7: 60+ | AU7: Normal | AV7: 0.88 | AW7: 4 | AX7: 0 | AY7: =IF(AND(OR(Overview!$B$10="All",AC7=Overview!$B$10),OR(Overview!$B$12="All",AD7=Overview!$B$12),OR(Overview!$B$14="All",AF7=Overview!$B$14),OR(Overview!$B$16="All",AT7=Overview!$B$16),OR(Overview!$B$18="All",AU7=Overview!$B$18)),1,0) -> 1 | AZ7: =IF(AND(OR('Dash 1'!$B$10="All",AC7='Dash 1'!$B$10),OR('Dash 1'!$B$12="All",AD7='Dash 1'!$B$12),OR('Dash 1'!$B$14="All",AF7='Dash 1'!$B$14),OR('Dash 1'!$B$16="All",AT7='Dash 1'!$B$16),OR('Dash 1'!$B$18="All",AU7='Dash 1'!$B$18)),1,0) -> 1 | BA7: =IF(AND(OR('Dash 2'!$B$10="All",AC7='Dash 2'!$B$10),OR('Dash 2'!$B$12="All",AD7='Dash 2'!$B$12),OR('Dash 2'!$B$14="All",AF7='Dash 2'!$B$14),OR('Dash 2'!$B$16="All",AT7='Dash 2'!$B$16),OR('Dash 2'!$B$18="All",AU7='Dash 2'!$B$18)),1,0) -> 1
A8: 5040 | B8: 11 | C8: 0 | D8: 0 | E8: 2 | F8: 27.94 | G8: 0 | H8: 4.98 | I8: 0.49 | J8: 8.97 | K8: 5.21 | L8: 7.24 | M8: 4.57 | N8: 0 | O8: 0 | P8: 0 | Q8: 0 | R8: 0 | S8: 0 | T8: 3.01 | U8: 3.84 | V8: 0 | W8: 1 | X8: 0 | Y8: 0 | Z8: 0 | AA8: 0 | AB8: 1 | AC8: Male | AD8: Caucasian | AE8: Bachelor's | AF8: No | AG8: No | AH8: No | AI8: No | AJ8: No | AK8: No | AL8: No | AM8: No | AN8: Yes | AO8: No | AP8: No | AQ8: No | AR8: No | AS8: Positive | AT8: 0-17 (Child) | AU8: Overweight | AV8: 0.78 | AW8: 1 | AX8: 0 | AY8: =IF(AND(OR(Overview!$B$10="All",AC8=Overview!$B$10),OR(Overview!$B$12="All",AD8=Overview!$B$12),OR(Overview!$B$14="All",AF8=Overview!$B$14),OR(Overview!$B$16="All",AT8=Overview!$B$16),OR(Overview!$B$18="All",AU8=Overview!$B$18)),1,0) -> 1 | AZ8: =IF(AND(OR('Dash 1'!$B$10="All",AC8='Dash 1'!$B$10),OR('Dash 1'!$B$12="All",AD8='Dash 1'!$B$12),OR('Dash 1'!$B$14="All",AF8='Dash 1'!$B$14),OR('Dash 1'!$B$16="All",AT8='Dash 1'!$B$16),OR('Dash 1'!$B$18="All",AU8='Dash 1'!$B$18)),1,0) -> 1 | BA8: =IF(AND(OR('Dash 2'!$B$10="All",AC8='Dash 2'!$B$10),OR('Dash 2'!$B$12="All",AD8='Dash 2'!$B$12),OR('Dash 2'!$B$14="All",AF8='Dash 2'!$B$14),OR('Dash 2'!$B$16="All",AT8='Dash 2'!$B$16),OR('Dash 2'!$B$18="All",AU8='Dash 2'!$B$18)),1,0) -> 1
A9: 5041 | B9: 57 | C9: 1 | D9: 1 | E9: 0 | F9: 23.47 | G9: 0 | H9: 5.3 | I9: 5.23 | J9: 5.32 | K9: 0 | L9: 8.14 | M9: 7.85 | N9: 1 | O9: 0 | P9: 1 | Q9: 0 | R9: 1 | S9: 0 | T9: 2.16 | U9: 2.67 | V9: 0 | W9: 1 | X9: 0 | Y9: 1 | Z9: 0 | AA9: 0 | AB9: 0 | AC9: Female | AD9: African American | AF9: No | AG9: Yes | AH9: No | AI9: Yes | AJ9: No | AK9: Yes | AL9: No | AM9: No | AN9: Yes | AO9: No | AP9: Yes | AQ9: No | AR9: No | AS9: Negative | AT9: 45-59 | AU9: Normal | AV9: 0.81 | AW9: 2 | AX9: 2 | AY9: =IF(AND(OR(Overview!$B$10="All",AC9=Overview!$B$10),OR(Overview!$B$12="All",AD9=Overview!$B$12),OR(Overview!$B$14="All",AF9=Overview!$B$14),OR(Overview!$B$16="All",AT9=Overview!$B$16),OR(Overview!$B$18="All",AU9=Overview!$B$18)),1,0) -> 1 | AZ9: =IF(AND(OR('Dash 1'!$B$10="All",AC9='Dash 1'!$B$10),OR('Dash 1'!$B$12="All",AD9='Dash 1'!$B$12),OR('Dash 1'!$B$14="All",AF9='Dash 1'!$B$14),OR('Dash 1'!$B$16="All",AT9='Dash 1'!$B$16),OR('Dash 1'!$B$18="All",AU9='Dash 1'!$B$18)),1,0) -> 1 | BA9: =IF(AND(OR('Dash 2'!$B$10="All",AC9='Dash 2'!$B$10),OR('Dash 2'!$B$12="All",AD9='Dash 2'!$B$12),OR('Dash 2'!$B$14="All",AF9='Dash 2'!$B$14),OR('Dash 2'!$B$16="All",AT9='Dash 2'!$B$16),OR('Dash 2'!$B$18="All",AU9='Dash 2'!$B$18)),1,0) -> 1
A10: 5042 | B10: 20 | C10: 0 | D10: 1 | E10: 1 | F10: 24.22 | G10: 0 | H10: 5.4 | I10: 5.81 | J10: 5.22 | K10: 6.94 | L10: 7.95 | M10: 5.2 | N10: 1 | O10: 1 | P10: 0 | Q10: 0 | R10: 1 | S10: 0 | T10: 2.02 | U10: 2.67 | V10: 1 | W10: 1 | X10: 0 | Y10: 1 | Z10: 1 | AA10: 1 | AB10: 1 | AC10: Male | AD10: African American | AE10: High School | AF10: No | AG10: Yes | AH10: Yes | AI10: No | AJ10: No | AK10: Yes | AL10: No | AM10: Yes | AN10: Yes | AO10: No | AP10: Yes | AQ10: Yes | AR10: Yes | AS10: Positive | AT10: 18-29 | AU10: Normal | AV10: 0.76 | AW10: 5 | AX10: 2 | AY10: =IF(AND(OR(Overview!$B$10="All",AC10=Overview!$B$10),OR(Overview!$B$12="All",AD10=Overview!$B$12),OR(Overview!$B$14="All",AF10=Overview!$B$14),OR(Overview!$B$16="All",AT10=Overview!$B$16),OR(Overview!$B$18="All",AU10=Overview!$B$18)),1,0) -> 1 | AZ10: =IF(AND(OR('Dash 1'!$B$10="All",AC10='Dash 1'!$B$10),OR('Dash 1'!$B$12="All",AD10='Dash 1'!$B$12),OR('Dash 1'!$B$14="All",AF10='Dash 1'!$B$14),OR('Dash 1'!$B$16="All",AT10='Dash 1'!$B$16),OR('Dash 1'!$B$18="All",AU10='Dash 1'!$B$18)),1,0) -> 1 | BA10: =IF(AND(OR('Dash 2'!$B$10="All",AC10='Dash 2'!$B$10),OR('Dash 2'!$B$12="All",AD10='Dash 2'!$B$12),OR('Dash 2'!$B$14="All",AF10='Dash 2'!$B$14),OR('Dash 2'!$B$16="All",AT10='Dash 2'!$B$16),OR('Dash 2'!$B$18="All",AU10='Dash 2'!$B$18)),1,0) -> 1
A11: 5043 | B11: 12 | C11: 1 | D11: 2 | E11: 3 | F11: 23.16 | G11: 0 | H11: 3.01 | I11: 4.52 | J11: 5.77 | K11: 6.22 | L11: 8.86 | M11: 7.76 | N11: 0 | O11: 0 | P11: 0 | Q11: 0 | R11: 0 | S11: 0 | T11: 2.3 | U11: 2.61 | V11: 0 | W11: 0 | X11: 1 | Y11: 0 | Z11: 1 | AA11: 0 | AB11: 1 | AC11: Female | AD11: Asian | AE11: Higher | AF11: No | AG11: No | AH11: No | AI11: No | AJ11: No | AK11: No | AL11: No | AM11: No | AN11: No | AO11: Yes | AP11: No | AQ11: Yes | AR11: No | AS11: Positive | AT11: 0-17 (Child) | AU11: Normal | AV11: 0.88 | AW11: 2 | AX11: 0 | AY11: =IF(AND(OR(Overview!$B$10="All",AC11=Overview!$B$10),OR(Overview!$B$12="All",AD11=Overview!$B$12),OR(Overview!$B$14="All",AF11=Overview!$B$14),OR(Overview!$B$16="All",AT11=Overview!$B$16),OR(Overview!$B$18="All",AU11=Overview!$B$18)),1,0) -> 1 | AZ11: =IF(AND(OR('Dash 1'!$B$10="All",AC11='Dash 1'!$B$10),OR('Dash 1'!$B$12="All",AD11='Dash 1'!$B$12),OR('Dash 1'!$B$14="All",AF11='Dash 1'!$B$14),OR('Dash 1'!$B$16="All",AT11='Dash 1'!$B$16),OR('Dash 1'!$B$18="All",AU11='Dash 1'!$B$18)),1,0) -> 1 | BA11: =IF(AND(OR('Dash 2'!$B$10="All",AC11='Dash 2'!$B$10),OR('Dash 2'!$B$12="All",AD11='Dash 2'!$B$12),OR('Dash 2'!$B$14="All",AF11='Dash 2'!$B$14),OR('Dash 2'!$B$16="All",AT11='Dash 2'!$B$16),OR('Dash 2'!$B$18="All",AU11='Dash 2'!$B$18)),1,0) -> 1
A12: 5044 | B12: 45 | C12: 1 | D12: 2 | E12: 1 | F12: 40 | G12: 0 | H12: 6.98 | I12: 6.12 | J12: 5 | K12: 2.54 | L12: 10 | M12: 8.25 | N12: 0 | O12: 0 | P12: 1 | Q12: 0 | R12: 0 | S12: 0 | T12: 2.12 | U12: 2.47 | V12: 0 | W12: 0 | X12: 1 | Y12: 1 | Z12: 0 | AA12: 0 | AB12: 0 | AC12: Female | AD12: Asian | AE12: High School | AF12: No | AG12: No | AH12: No | AI12: Yes | AJ12: No | AK12: No | AL12: No | AM12: No | AN12: No | AO12: Yes | AP12: Yes | AQ12: No | AR12: No | AS12: Negative | AT12: 45-59 | AU12: Obese | AV12: 0.86 | AW12: 2 | AX12: 1 | AY12: =IF(AND(OR(Overview!$B$10="All",AC12=Overview!$B$10),OR(Overview!$B$12="All",AD12=Overview!$B$12),OR(Overview!$B$14="All",AF12=Overview!$B$14),OR(Overview!$B$16="All",AT12=Overview!$B$16),OR(Overview!$B$18="All",AU12=Overview!$B$18)),1,0) -> 1 | AZ12: =IF(AND(OR('Dash 1'!$B$10="All",AC12='Dash 1'!$B$10),OR('Dash 1'!$B$12="All",AD12='Dash 1'!$B$12),OR('Dash 1'!$B$14="All",AF12='Dash 1'!$B$14),OR('Dash 1'!$B$16="All",AT12='Dash 1'!$B$16),OR('Dash 1'!$B$18="All",AU12='Dash 1'!$B$18)),1,0) -> 1 | BA12: =IF(AND(OR('Dash 2'!$B$10="All",AC12='Dash 2'!$B$10),OR('Dash 2'!$B$12="All",AD12='Dash 2'!$B$12),OR('Dash 2'!$B$14="All",AF12='Dash 2'!$B$14),OR('Dash 2'!$B$16="All",AT12='Dash 2'!$B$16),OR('Dash 2'!$B$18="All",AU12='Dash 2'!$B$18)),1,0) -> 1
A13: 5045 | B13: 79 | C13: 1 | D13: 2 | E13: 1 | F13: 22.69 | G13: 0 | H13: 4.8 | I13: 1.85 | J13: 5.09 | K13: 5.7 | L13: 9.32 | M13: 0.61 | N13: 1 | O13: 0 | P13: 0 | Q13: 1 | R13: 1 | S13: 0 | T13: 2.81 | U13: 3.51 | V13: 0 | W13: 1 | X13: 1 | Y13: 1 | Z13: 1 | AA13: 1 | AB13: 1 | AC13: Female | AD13: Asian | AE13: High School | AF13: No | AG13: Yes | AH13: No | AI13: No | AJ13: Yes | AK13: Yes | AL13: No | AM13: No | AN13: Yes | AO13: Yes | AP13: Yes | AQ13: Yes | AR13: Yes | AS13: Positive | AT13: 60+ | AU13: Normal | AV13: 0.8 | AW13: 5 | AX13: 2 | AY13: =IF(AND(OR(Overview!$B$10="All",AC13=Overview!$B$10),OR(Overview!$B$12="All",AD13=Overview!$B$12),OR(Overview!$B$14="All",AF13=Overview!$B$14),OR(Overview!$B$16="All",AT13=Overview!$B$16),OR(Overview!$B$18="All",AU13=Overview!$B$18)),1,0) -> 1 | AZ13: =IF(AND(OR('Dash 1'!$B$10="All",AC13='Dash 1'!$B$10),OR('Dash 1'!$B$12="All",AD13='Dash 1'!$B$12),OR('Dash 1'!$B$14="All",AF13='Dash 1'!$B$14),OR('Dash 1'!$B$16="All",AT13='Dash 1'!$B$16),OR('Dash 1'!$B$18="All",AU13='Dash 1'!$B$18)),1,0) -> 1 | BA13: =IF(AND(OR('Dash 2'!$B$10="All",AC13='Dash 2'!$B$10),OR('Dash 2'!$B$12="All",AD13='Dash 2'!$B$12),OR('Dash 2'!$B$14="All",AF13='Dash 2'!$B$14),OR('Dash 2'!$B$16="All",AT13='Dash 2'!$B$16),OR('Dash 2'!$B$18="All",AU13='Dash 2'!$B$18)),1,0) -> 1
A14: 5046 | B14: 60 | C14: 0 | D14: 2 | E14: 1 | F14: 15.66 | G14: 0 | H14: 5.97 | I14: 0 | J14: 5.74 | K14: 6.62 | L14: 5.85 | M14: 0 | N14: 0 | O14: 0 | P14: 1 | Q14: 0 | R14: 1 | S14: 0 | T14: 2.96 | U14: 3.95 | V14: 0 | W14: 0 | X14: 1 | Y14: 1 | Z14: 0 | AA14: 1 | AB14: 1 | AC14: Male | AD14: Asian | AE14: High School | AF14: No | AG14: No | AH14: No | AI14: Yes | AJ14: No | AK14: Yes | AL14: No | AM14: No | AN14: No | AO14: Yes | AP14: Yes | AQ14: No | AR14: Yes | AS14: Positive | AT14: 60+ | AU14: Underweight | AV14: 0.75 | AW14: 3 | AX14: 2 | AY14: =IF(AND(OR(Overview!$B$10="All",AC14=Overview!$B$10),OR(Overview!$B$12="All",AD14=Overview!$B$12),OR(Overview!$B$14="All",AF14=Overview!$B$14),OR(Overview!$B$16="All",AT14=Overview!$B$16),OR(Overview!$B$18="All",AU14=Overview!$B$18)),1,0) -> 1 | AZ14: =IF(AND(OR('Dash 1'!$B$10="All",AC14='Dash 1'!$B$10),OR('Dash 1'!$B$12="All",AD14='Dash 1'!$B$12),OR('Dash 1'!$B$14="All",AF14='Dash 1'!$B$14),OR('Dash 1'!$B$16="All",AT14='Dash 1'!$B$16),OR('Dash 1'!$B$18="All",AU14='Dash 1'!$B$18)),1,0) -> 1 | BA14: =IF(AND(OR('Dash 2'!$B$10="All",AC14='Dash 2'!$B$10),OR('Dash 2'!$B$12="All",AD14='Dash 2'!$B$12),OR('Dash 2'!$B$14="All",AF14='Dash 2'!$B$14),OR('Dash 2'!$B$16="All",AT14='Dash 2'!$B$16),OR('Dash 2'!$B$18="All",AU14='Dash 2'!$B$18)),1,0) -> 1
A15: 5047 | B15: 62 | C15: 1 | D15: 0 | E15: 2 | F15: 18 | G15: 0 | H15: 2.37 | I15: 3.15 | J15: 8.6 | K15: 7.93 | L15: 4.48 | M15: 7.91 | N15: 0 | O15: 0 | P15: 0 | Q15: 0 | R15: 0 | S15: 1 | T15: 2.5 | U15: 2.82 | V15: 0 | W15: 0 | X15: 1 | Y15: 1 | Z15: 0 | AA15: 0 | AB15: 1 | AC15: Female | AD15: Caucasian | AE15: Bachelor's | AF15: No | AG15: No | AH15: No | AI15: No | AJ15: No | AK15: No | AL15: Yes | AM15: No | AN15: No | AO15: Yes | AP15: Yes | AQ15: No | AR15: No | AS15: Positive | AT15: 60+ | AU15: Underweight | AV15: 0.89 | AW15: 2 | AX15: 1 | AY15: =IF(AND(OR(Overview!$B$10="All",AC15=Overview!$B$10),OR(Overview!$B$12="All",AD15=Overview!$B$12),OR(Overview!$B$14="All",AF15=Overview!$B$14),OR(Overview!$B$16="All",AT15=Overview!$B$16),OR(Overview!$B$18="All",AU15=Overview!$B$18)),1,0) -> 1 | AZ15: =IF(AND(OR('Dash 1'!$B$10="All",AC15='Dash 1'!$B$10),OR('Dash 1'!$B$12="All",AD15='Dash 1'!$B$12),OR('Dash 1'!$B$14="All",AF15='Dash 1'!$B$14),OR('Dash 1'!$B$16="All",AT15='Dash 1'!$B$16),OR('Dash 1'!$B$18="All",AU15='Dash 1'!$B$18)),1,0) -> 1 | BA15: =IF(AND(OR('Dash 2'!$B$10="All",AC15='Dash 2'!$B$10),OR('Dash 2'!$B$12="All",AD15='Dash 2'!$B$12),OR('Dash 2'!$B$14="All",AF15='Dash 2'!$B$14),OR('Dash 2'!$B$16="All",AT15='Dash 2'!$B$16),OR('Dash 2'!$B$18="All",AU15='Dash 2'!$B$18)),1,0) -> 1
A16: 5048 | B16: 59 | C16: 0 | D16: 1 | E16: 3 | F16: 29.8 | G16: 0 | H16: 4.61 | I16: 6.01 | J16: 6.59 | K16: 6.28 | L16: 0.43 | M16: 8.01 | N16: 0 | O16: 0 | P16: 1 | Q16: 0 | R16: 1 | S16: 0 | T16: 2.28 | U16: 2.53 | V16: 0 | W16: 0 | X16: 1 | Y16: 1 | Z16: 0 | AA16: 0 | AB16: 1 | AC16: Male | AD16: African American | AE16: Higher | AF16: No | AG16: No | AH16: No | AI16: Yes | AJ16: No | AK16: Yes | AL16: No | AM16: No | AN16: No | AO16: Yes | AP16: Yes | AQ16: No | AR16: No | AS16: Positive | AT16: 45-59 | AU16: Overweight | AV16: 0.9 | AW16: 2 | AX16: 2 | AY16: =IF(AND(OR(Overview!$B$10="All",AC16=Overview!$B$10),OR(Overview!$B$12="All",AD16=Overview!$B$12),OR(Overview!$B$14="All",AF16=Overview!$B$14),OR(Overview!$B$16="All",AT16=Overview!$B$16),OR(Overview!$B$18="All",AU16=Overview!$B$18)),1,0) -> 1 | AZ16: =IF(AND(OR('Dash 1'!$B$10="All",AC16='Dash 1'!$B$10),OR('Dash 1'!$B$12="All",AD16='Dash 1'!$B$12),OR('Dash 1'!$B$14="All",AF16='Dash 1'!$B$14),OR('Dash 1'!$B$16="All",AT16='Dash 1'!$B$16),OR('Dash 1'!$B$18="All",AU16='Dash 1'!$B$18)),1,0) -> 1 | BA16: =IF(AND(OR('Dash 2'!$B$10="All",AC16='Dash 2'!$B$10),OR('Dash 2'!$B$12="All",AD16='Dash 2'!$B$12),OR('Dash 2'!$B$14="All",AF16='Dash 2'!$B$14),OR('Dash 2'!$B$16="All",AT16='Dash 2'!$B$16),OR('Dash 2'!$B$18="All",AU16='Dash 2'!$B$18)),1,0) -> 1
A17: 5049 | B17: 64 | C17: 1 | D17: 0 | E17: 2 | F17: 32.68 | G17: 0 | H17: 7.41 | I17: 0 | J17: 7.04 | K17: 5.8 | L17: 5.03 | M17: 5.64 | N17: 1 | O17: 0 | P17: 0 | Q17: 0 | R17: 1 | S17: 1 | T17: 3.52 | U17: 4.46 | V17: 0 | W17: 1 | X17: 0 | Y17: 1 | Z17: 1 | AA17: 0 | AB17: 1 | AC17: Female | AD17: Caucasian | AE17: Bachelor's | AF17: No | AG17: Yes | AH17: No | AI17: No | AJ17: No | AK17: Yes | AL17: Yes | AM17: No | AN17: Yes | AO17: No | AP17: Yes | AQ17: Yes | AR17: No | AS17: Positive | AT17: 60+ | AU17: Obese | AV17: 0.79 | AW17: 3 | AX17: 2 | AY17: =IF(AND(OR(Overview!$B$10="All",AC17=Overview!$B$10),OR(Overview!$B$12="All",AD17=Overview!$B$12),OR(Overview!$B$14="All",AF17=Overview!$B$14),OR(Overview!$B$16="All",AT17=Overview!$B$16),OR(Overview!$B$18="All",AU17=Overview!$B$18)),1,0) -> 1 | AZ17: =IF(AND(OR('Dash 1'!$B$10="All",AC17='Dash 1'!$B$10),OR('Dash 1'!$B$12="All",AD17='Dash 1'!$B$12),OR('Dash 1'!$B$14="All",AF17='Dash 1'!$B$14),OR('Dash 1'!$B$16="All",AT17='Dash 1'!$B$16),OR('Dash 1'!$B$18="All",AU17='Dash 1'!$B$18)),1,0) -> 1 | BA17: =IF(AND(OR('Dash 2'!$B$10="All",AC17='Dash 2'!$B$10),OR('Dash 2'!$B$12="All",AD17='Dash 2'!$B$12),OR('Dash 2'!$B$14="All",AF17='Dash 2'!$B$14),OR('Dash 2'!$B$16="All",AT17='Dash 2'!$B$16),OR('Dash 2'!$B$18="All",AU17='Dash 2'!$B$18)),1,0) -> 1
A18: 5050 | B18: 44 | C18: 0 | D18: 0 | E18: 1 | F18: 22.59 | G18: 0 | H18: 7.13 | I18: 4.13 | J18: 5.76 | K18: 7.37 | L18: 6.3 | M18: 5.98 | N18: 0 | O18: 0 | P18: 0 | Q18: 0 | R18: 0 | S18: 0 | T18: 3.61 | U18: 4.36 | V18: 0 | W18: 0 | X18: 0 | Y18: 0 | Z18: 0 | AA18: 0 | AB18: 0 | AC18: Male | AD18: Caucasian | AE18: High School | AF18: No | AG18: No | AH18: No | AI18: No | AJ18: No | AK18: No | AL18: No | AM18: No | AN18: No | AO18: No | AP18: No | AQ18: No | AR18: No | AS18: Negative | AT18: 30-44 | AU18: Normal | AV18: 0.83 | AW18: 0 | AX18: 0 | AY18: =IF(AND(OR(Overview!$B$10="All",AC18=Overview!$B$10),OR(Overview!$B$12="All",AD18=Overview!$B$12),OR(Overview!$B$14="All",AF18=Overview!$B$14),OR(Overview!$B$16="All",AT18=Overview!$B$16),OR(Overview!$B$18="All",AU18=Overview!$B$18)),1,0) -> 1 | AZ18: =IF(AND(OR('Dash 1'!$B$10="All",AC18='Dash 1'!$B$10),OR('Dash 1'!$B$12="All",AD18='Dash 1'!$B$12),OR('Dash 1'!$B$14="All",AF18='Dash 1'!$B$14),OR('Dash 1'!$B$16="All",AT18='Dash 1'!$B$16),OR('Dash 1'!$B$18="All",AU18='Dash 1'!$B$18)),1,0) -> 1 | BA18: =IF(AND(OR('Dash 2'!$B$10="All",AC18='Dash 2'!$B$10),OR('Dash 2'!$B$12="All",AD18='Dash 2'!$B$12),OR('Dash 2'!$B$14="All",AF18='Dash 2'!$B$14),OR('Dash 2'!$B$16="All",AT18='Dash 2'!$B$16),OR('Dash 2'!$B$18="All",AU18='Dash 2'!$B$18)),1,0) -> 1
A19: 5051 | B19: 14 | C19: 0 | D19: 3 | E19: 1 | F19: 32.39 | G19: 0 | H19: 3.25 | I19: 1.39 | J19: 7.82 | K19: 4.23 | L19: 5.11 | M19: 7.23 | N19: 0 | O19: 0 | P19: 0 | Q19: 0 | R19: 0 | S19: 0 | T19: 2.78 | U19: 3.23 | V19: 0 | W19: 0 | X19: 1 | Y19: 0 | Z19: 0 | AA19: 1 | AB19: 0 | AC19: Male | AD19: Other | AE19: High School | AF19: No | AG19: No | AH19: No | AI19: No | AJ19: No | AK19: No | AL19: No | AM19: No | AN19: No | AO19: Yes | AP19: No | AQ19: No | AR19: Yes | AS19: Negative | AT19: 0-17 (Child) | AU19: Obese | AV19: 0.86 | AW19: 2 | AX19: 0 | AY19: =IF(AND(OR(Overview!$B$10="All",AC19=Overview!$B$10),OR(Overview!$B$12="All",AD19=Overview!$B$12),OR(Overview!$B$14="All",AF19=Overview!$B$14),OR(Overview!$B$16="All",AT19=Overview!$B$16),OR(Overview!$B$18="All",AU19=Overview!$B$18)),1,0) -> 1 | AZ19: =IF(AND(OR('Dash 1'!$B$10="All",AC19='Dash 1'!$B$10),OR('Dash 1'!$B$12="All",AD19='Dash 1'!$B$12),OR('Dash 1'!$B$14="All",AF19='Dash 1'!$B$14),OR('Dash 1'!$B$16="All",AT19='Dash 1'!$B$16),OR('Dash 1'!$B$18="All",AU19='Dash 1'!$B$18)),1,0) -> 1 | BA19: =IF(AND(OR('Dash 2'!$B$10="All",AC19='Dash 2'!$B$10),OR('Dash 2'!$B$12="All",AD19='Dash 2'!$B$12),OR('Dash 2'!$B$14="All",AF19='Dash 2'!$B$14),OR('Dash 2'!$B$16="All",AT19='Dash 2'!$B$16),OR('Dash 2'!$B$18="All",AU19='Dash 2'!$B$18)),1,0) -> 1
A20: 5052 | B20: 68 | C20: 1 | D20: 1 | E20: 0 | F20: 29.71 | G20: 0 | H20: 3.8 | I20: 4.83 | J20: 9.44 | K20: 6.03 | L20: 0.28 | M20: 7.19 | N20: 0 | O20: 1 | P20: 1 | Q20: 0 | R20: 1 | S20: 0 | T20: 3.3 | U20: 4.82 | V20: 0 | W20: 0 | X20: 1 | Y20: 1 | Z20: 1 | AA20: 1 | AB20: 0 | AC20: Female | AD20: African American | AF20: No | AG20: No | AH20: Yes | AI20: Yes | AJ20: No | AK20: Yes | AL20: No | AM20: No | AN20: No | AO20: Yes | AP20: Yes | AQ20: Yes | AR20: Yes | AS20: Negative | AT20: 60+ | AU20: Overweight | AV20: 0.68 | AW20: 4 | AX20: 3 | AY20: =IF(AND(OR(Overview!$B$10="All",AC20=Overview!$B$10),OR(Overview!$B$12="All",AD20=Overview!$B$12),OR(Overview!$B$14="All",AF20=Overview!$B$14),OR(Overview!$B$16="All",AT20=Overview!$B$16),OR(Overview!$B$18="All",AU20=Overview!$B$18)),1,0) -> 1 | AZ20: =IF(AND(OR('Dash 1'!$B$10="All",AC20='Dash 1'!$B$10),OR('Dash 1'!$B$12="All",AD20='Dash 1'!$B$12),OR('Dash 1'!$B$14="All",AF20='Dash 1'!$B$14),OR('Dash 1'!$B$16="All",AT20='Dash 1'!$B$16),OR('Dash 1'!$B$18="All",AU20='Dash 1'!$B$18)),1,0) -> 1 | BA20: =IF(AND(OR('Dash 2'!$B$10="All",AC20='Dash 2'!$B$10),OR('Dash 2'!$B$12="All",AD20='Dash 2'!$B$12),OR('Dash 2'!$B$14="All",AF20='Dash 2'!$B$14),OR('Dash 2'!$B$16="All",AT20='Dash 2'!$B$16),OR('Dash 2'!$B$18="All",AU20='Dash 2'!$B$18)),1,0) -> 1
A21: 5053 | B21: 39 | C21: 0 | D21: 3 | E21: 2 | F21: 26.05 | G21: 1 | H21: 1.62 | I21: 8.91 | J21: 5.45 | K21: 3.45 | L21: 4.28 | M21: 4.24 | N21: 0 | O21: 0 | P21: 1 | Q21: 1 | R21: 0 | S21: 0 | T21: 2.58 | U21: 3.12 | V21: 1 | W21: 1 | X21: 1 | Y21: 1 | Z21: 0 | AA21: 0 | AB21: 1 | AC21: Male | AD21: Other | AE21: Bachelor's | AF21: Yes | AG21: No | AH21: No | AI21: Yes | AJ21: Yes | AK21: No | AL21: No | AM21: Yes | AN21: Yes | AO21: Yes | AP21: Yes | AQ21: No | AR21: No | AS21: Positive | AT21: 30-44 | AU21: Overweight | AV21: 0.82 | AW21: 4 | AX21: 2 | AY21: =IF(AND(OR(Overview!$B$10="All",AC21=Overview!$B$10),OR(Overview!$B$12="All",AD21=Overview!$B$12),OR(Overview!$B$14="All",AF21=Overview!$B$14),OR(Overview!$B$16="All",AT21=Overview!$B$16),OR(Overview!$B$18="All",AU21=Overview!$B$18)),1,0) -> 1 | AZ21: =IF(AND(OR('Dash 1'!$B$10="All",AC21='Dash 1'!$B$10),OR('Dash 1'!$B$12="All",AD21='Dash 1'!$B$12),OR('Dash 1'!$B$14="All",AF21='Dash 1'!$B$14),OR('Dash 1'!$B$16="All",AT21='Dash 1'!$B$16),OR('Dash 1'!$B$18="All",AU21='Dash 1'!$B$18)),1,0) -> 1 | BA21: =IF(AND(OR('Dash 2'!$B$10="All",AC21='Dash 2'!$B$10),OR('Dash 2'!$B$12="All",AD21='Dash 2'!$B$12),OR('Dash 2'!$B$14="All",AF21='Dash 2'!$B$14),OR('Dash 2'!$B$16="All",AT21='Dash 2'!$B$16),OR('Dash 2'!$B$18="All",AU21='Dash 2'!$B$18)),1,0) -> 1
A22: 5054 | B22: 43 | C22: 1 | D22: 0 | E22: 3 | F22: 24.7 | G22: 0 | H22: 3.56 | I22: 4.85 | J22: 9.24 | K22: 7.78 | L22: 6.61 | M22: 7.39 | N22: 1 | O22: 0 | P22: 1 | Q22: 0 | R22: 1 | S22: 0 | T22: 2.9 | U22: 3.48 | V22: 1 | W22: 1 | X22: 0 | Y22: 0 | Z22: 0 | AA22: 0 | AB22: 0 | AC22: Female | AD22: Caucasian | AE22: Higher | AF22: No | AG22: Yes | AH22: No | AI22: Yes | AJ22: No | AK22: Yes | AL22: No | AM22: Yes | AN22: Yes | AO22: No | AP22: No | AQ22: No | AR22: No | AS22: Negative | AT22: 30-44 | AU22: Normal | AV22: 0.83 | AW22: 2 | AX22: 2 | AY22: =IF(AND(OR(Overview!$B$10="All",AC22=Overview!$B$10),OR(Overview!$B$12="All",AD22=Overview!$B$12),OR(Overview!$B$14="All",AF22=Overview!$B$14),OR(Overview!$B$16="All",AT22=Overview!$B$16),OR(Overview!$B$18="All",AU22=Overview!$B$18)),1,0) -> 1 | AZ22: =IF(AND(OR('Dash 1'!$B$10="All",AC22='Dash 1'!$B$10),OR('Dash 1'!$B$12="All",AD22='Dash 1'!$B$12),OR('Dash 1'!$B$14="All",AF22='Dash 1'!$B$14),OR('Dash 1'!$B$16="All",AT22='Dash 1'!$B$16),OR('Dash 1'!$B$18="All",AU22='Dash 1'!$B$18)),1,0) -> 1 | BA22: =IF(AND(OR('Dash 2'!$B$10="All",AC22='Dash 2'!$B$10),OR('Dash 2'!$B$12="All",AD22='Dash 2'!$B$12),OR('Dash 2'!$B$14="All",AF22='Dash 2'!$B$14),OR('Dash 2'!$B$16="All",AT22='Dash 2'!$B$16),OR('Dash 2'!$B$18="All",AU22='Dash 2'!$B$18)),1,0) -> 1
A23: 5055 | B23: 33 | C23: 1 | D23: 0 | E23: 2 | F23: 27.9 | G23: 1 | H23: 0.72 | I23: 4.64 | J23: 7.07 | K23: 0.98 | L23: 2.44 | M23: 4.13 | N23: 0 | O23: 1 | P23: 0 | Q23: 0 | R23: 0 | S23: 0 | T23: 2.32 | U23: 3.01 | V23: 1 | W23: 1 | X23: 1 | Y23: 0 | Z23: 0 | AA23: 1 | AB23: 1 | AC23: Female | AD23: Caucasian | AE23: Bachelor's | AF23: Yes | AG23: No | AH23: Yes | AI23: No | AJ23: No | AK23: No | AL23: No | AM23: Yes | AN23: Yes | AO23: Yes | AP23: No | AQ23: No | AR23: Yes | AS23: Positive | AT23: 30-44 | AU23: Overweight | AV23: 0.77 | AW23: 4 | AX23: 1 | AY23: =IF(AND(OR(Overview!$B$10="All",AC23=Overview!$B$10),OR(Overview!$B$12="All",AD23=Overview!$B$12),OR(Overview!$B$14="All",AF23=Overview!$B$14),OR(Overview!$B$16="All",AT23=Overview!$B$16),OR(Overview!$B$18="All",AU23=Overview!$B$18)),1,0) -> 1 | AZ23: =IF(AND(OR('Dash 1'!$B$10="All",AC23='Dash 1'!$B$10),OR('Dash 1'!$B$12="All",AD23='Dash 1'!$B$12),OR('Dash 1'!$B$14="All",AF23='Dash 1'!$B$14),OR('Dash 1'!$B$16="All",AT23='Dash 1'!$B$16),OR('Dash 1'!$B$18="All",AU23='Dash 1'!$B$18)),1,0) -> 1 | BA23: =IF(AND(OR('Dash 2'!$B$10="All",AC23='Dash 2'!$B$10),OR('Dash 2'!$B$12="All",AD23='Dash 2'!$B$12),OR('Dash 2'!$B$14="All",AF23='Dash 2'!$B$14),OR('Dash 2'!$B$16="All",AT23='Dash 2'!$B$16),OR('Dash 2'!$B$18="All",AU23='Dash 2'!$B$18)),1,0) -> 1
A24: 5056 | B24: 18 | C24: 0 | D24: 0 | E24: 1 | F24: 30.39 | G24: 0 | H24: 4.7 | I24: 7.13 | J24: 7.02 | K24: 7.04 | L24: 5.41 | M24: 5.61 | N24: 0 | O24: 0 | P24: 0 | Q24: 0 | R24: 0 | S24: 0 | T24: 2.9 | U24: 4.08 | V24: 0 | W24: 1 | X24: 0 | Y24: 0 | Z24: 0 | AA24: 0 | AB24: 0 | AC24: Male | AD24: Caucasian | AE24: High School | AF24: No | AG24: No | AH24: No | AI24: No | AJ24: No | AK24: No | AL24: No | AM24: No | AN24: Yes | AO24: No | AP24: No | AQ24: No | AR24: No | AS24: Negative | AT24: 18-29 | AU24: Obese | AV24: 0.71 | AW24: 1 | AX24: 0 | AY24: =IF(AND(OR(Overview!$B$10="All",AC24=Overview!$B$10),OR(Overview!$B$12="All",AD24=Overview!$B$12),OR(Overview!$B$14="All",AF24=Overview!$B$14),OR(Overview!$B$16="All",AT24=Overview!$B$16),OR(Overview!$B$18="All",AU24=Overview!$B$18)),1,0) -> 1 | AZ24: =IF(AND(OR('Dash 1'!$B$10="All",AC24='Dash 1'!$B$10),OR('Dash 1'!$B$12="All",AD24='Dash 1'!$B$12),OR('Dash 1'!$B$14="All",AF24='Dash 1'!$B$14),OR('Dash 1'!$B$16="All",AT24='Dash 1'!$B$16),OR('Dash 1'!$B$18="All",AU24='Dash 1'!$B$18)),1,0) -> 1 | BA24: =IF(AND(OR('Dash 2'!$B$10="All",AC24='Dash 2'!$B$10),OR('Dash 2'!$B$12="All",AD24='Dash 2'!$B$12),OR('Dash 2'!$B$14="All",AF24='Dash 2'!$B$14),OR('Dash 2'!$B$16="All",AT24='Dash 2'!$B$16),OR('Dash 2'!$B$18="All",AU24='Dash 2'!$B$18)),1,0) -> 1
A25: 5057 | B25: 75 | C25: 0 | D25: 0 | E25: 2 | F25: 27.99 | G25: 0 | H25: 6.39 | I25: 5.75 | J25: 7.52 | K25: 5.04 | L25: 6.08 | M25: 5.5 | N25: 0 | O25: 0 | P25: 0 | Q25: 0 | R25: 1 | S25: 1 | T25: 2.08 | U25: 2.6 | V25: 0 | W25: 0 | X25: 0 | Y25: 1 | Z25: 0 | AA25: 1 | AB25: 1 | AC25: Male | AD25: Caucasian | AE25: Bachelor's | AF25: No | AG25: No | AH25: No | AI25: No | AJ25: No | AK25: Yes | AL25: Yes | AM25: No | AN25: No | AO25: No | AP25: Yes | AQ25: No | AR25: Yes | AS25: Positive | AT25: 60+ | AU25: Overweight | AV25: 0.8 | AW25: 2 | AX25: 2 | AY25: =IF(AND(OR(Overview!$B$10="All",AC25=Overview!$B$10),OR(Overview!$B$12="All",AD25=Overview!$B$12),OR(Overview!$B$14="All",AF25=Overview!$B$14),OR(Overview!$B$16="All",AT25=Overview!$B$16),OR(Overview!$B$18="All",AU25=Overview!$B$18)),1,0) -> 1 | AZ25: =IF(AND(OR('Dash 1'!$B$10="All",AC25='Dash 1'!$B$10),OR('Dash 1'!$B$12="All",AD25='Dash 1'!$B$12),OR('Dash 1'!$B$14="All",AF25='Dash 1'!$B$14),OR('Dash 1'!$B$16="All",AT25='Dash 1'!$B$16),OR('Dash 1'!$B$18="All",AU25='Dash 1'!$B$18)),1,0) -> 1 | BA25: =IF(AND(OR('Dash 2'!$B$10="All",AC25='Dash 2'!$B$10),OR('Dash 2'!$B$12="All",AD25='Dash 2'!$B$12),OR('Dash 2'!$B$14="All",AF25='Dash 2'!$B$14),OR('Dash 2'!$B$16="All",AT25='Dash 2'!$B$16),OR('Dash 2'!$B$18="All",AU25='Dash 2'!$B$18)),1,0) -> 1
A26: 5058 | B26: 64 | C26: 1 | D26: 0 | E26: 1 | F26: 22.62 | G26: 0 | H26: 3.27 | I26: 4.81 | J26: 7.51 | K26: 7.41 | L26: 7.79 | M26: 2.85 | N26: 0 | O26: 0 | P26: 1 | Q26: 0 | R26: 0 | S26: 0 | T26: 3.73 | U26: 5.11 | V26: 1 | W26: 1 | X26: 1 | Y26: 0 | Z26: 0 | AA26: 0 | AB26: 1 | AC26: Female | AD26: Caucasian | AE26: High School | AF26: No | AG26: No | AH26: No | AI26: Yes | AJ26: No | AK26: No | AL26: No | AM26: Yes | AN26: Yes | AO26: Yes | AP26: No | AQ26: No | AR26: No | AS26: Positive | AT26: 60+ | AU26: Normal | AV26: 0.73 | AW26: 3 | AX26: 1 | AY26: =IF(AND(OR(Overview!$B$10="All",AC26=Overview!$B$10),OR(Overview!$B$12="All",AD26=Overview!$B$12),OR(Overview!$B$14="All",AF26=Overview!$B$14),OR(Overview!$B$16="All",AT26=Overview!$B$16),OR(Overview!$B$18="All",AU26=Overview!$B$18)),1,0) -> 1 | AZ26: =IF(AND(OR('Dash 1'!$B$10="All",AC26='Dash 1'!$B$10),OR('Dash 1'!$B$12="All",AD26='Dash 1'!$B$12),OR('Dash 1'!$B$14="All",AF26='Dash 1'!$B$14),OR('Dash 1'!$B$16="All",AT26='Dash 1'!$B$16),OR('Dash 1'!$B$18="All",AU26='Dash 1'!$B$18)),1,0) -> 1 | BA26: =IF(AND(OR('Dash 2'!$B$10="All",AC26='Dash 2'!$B$10),OR('Dash 2'!$B$12="All",AD26='Dash 2'!$B$12),OR('Dash 2'!$B$14="All",AF26='Dash 2'!$B$14),OR('Dash 2'!$B$16="All",AT26='Dash 2'!$B$16),OR('Dash 2'!$B$18="All",AU26='Dash 2'!$B$18)),1,0) -> 1
A27: 5059 | B27: 53 | C27: 0 | D27: 0 | E27: 2 | F27: 25.13 | G27: 0 | H27: 4.8 | I27: 7.32 | J27: 9.41 | K27: 3.05 | L27: 9.28 | M27: 3.14 | N27: 0 | O27: 0 | P27: 0 | Q27: 0 | R27: 0 | S27: 0 | T27: 2.62 | U27: 3.6 | V27: 0 | W27: 0 | X27: 0 | Y27: 1 | Z27: 0 | AA27: 1 | AB27: 0 | AC27: Male | AD27: Caucasian | AE27: Bachelor's | AF27: No | AG27: No | AH27: No | AI27: No | AJ27: No | AK27: No | AL27: No | AM27: No | AN27: No | AO27: No | AP27: Yes | AQ27: No | AR27: Yes | AS27: Negative | AT27: 45-59 | AU27: Overweight | AV27: 0.73 | AW27: 2 | AX27: 0 | AY27: =IF(AND(OR(Overview!$B$10="All",AC27=Overview!$B$10),OR(Overview!$B$12="All",AD27=Overview!$B$12),OR(Overview!$B$14="All",AF27=Overview!$B$14),OR(Overview!$B$16="All",AT27=Overview!$B$16),OR(Overview!$B$18="All",AU27=Overview!$B$18)),1,0) -> 1 | AZ27: =IF(AND(OR('Dash 1'!$B$10="All",AC27='Dash 1'!$B$10),OR('Dash 1'!$B$12="All",AD27='Dash 1'!$B$12),OR('Dash 1'!$B$14="All",AF27='Dash 1'!$B$14),OR('Dash 1'!$B$16="All",AT27='Dash 1'!$B$16),OR('Dash 1'!$B$18="All",AU27='Dash 1'!$B$18)),1,0) -> 1 | BA27: =IF(AND(OR('Dash 2'!$B$10="All",AC27='Dash 2'!$B$10),OR('Dash 2'!$B$12="All",AD27='Dash 2'!$B$12),OR('Dash 2'!$B$14="All",AF27='Dash 2'!$B$14),OR('Dash 2'!$B$16="All",AT27='Dash 2'!$B$16),OR('Dash 2'!$B$18="All",AU27='Dash 2'!$B$18)),1,0) -> 1
A28: 5060 | B28: 35 | C28: 0 | D28: 0 | E28: 2 | F28: 35.91 | G28: 0 | H28: 4.51 | I28: 6.37 | J28: 7.68 | K28: 5.22 | L28: 4.06 | M28: 10 | N28: 0 | O28: 0 | P28: 0 | Q28: 0 | R28: 0 | S28: 0 | T28: 3.08 | U28: 3.69 | V28: 0 | W28: 0 | X28: 0 | Y28: 0 | Z28: 1 | AA28: 0 | AB28: 0 | AC28: Male | AD28: Caucasian | AE28: Bachelor's | AF28: No | AG28: No | AH28: No | AI28: No | AJ28: No | AK28: No | AL28: No | AM28: No | AN28: No | AO28: No | AP28: No | AQ28: Yes | AR28: No | AS28: Negative | AT28: 30-44 | AU28: Obese | AV28: 0.83 | AW28: 1 | AX28: 0 | AY28: =IF(AND(OR(Overview!$B$10="All",AC28=Overview!$B$10),OR(Overview!$B$12="All",AD28=Overview!$B$12),OR(Overview!$B$14="All",AF28=Overview!$B$14),OR(Overview!$B$16="All",AT28=Overview!$B$16),OR(Overview!$B$18="All",AU28=Overview!$B$18)),1,0) -> 1 | AZ28: =IF(AND(OR('Dash 1'!$B$10="All",AC28='Dash 1'!$B$10),OR('Dash 1'!$B$12="All",AD28='Dash 1'!$B$12),OR('Dash 1'!$B$14="All",AF28='Dash 1'!$B$14),OR('Dash 1'!$B$16="All",AT28='Dash 1'!$B$16),OR('Dash 1'!$B$18="All",AU28='Dash 1'!$B$18)),1,0) -> 1 | BA28: =IF(AND(OR('Dash 2'!$B$10="All",AC28='Dash 2'!$B$10),OR('Dash 2'!$B$12="All",AD28='Dash 2'!$B$12),OR('Dash 2'!$B$14="All",AF28='Dash 2'!$B$14),OR('Dash 2'!$B$16="All",AT28='Dash 2'!$B$16),OR('Dash 2'!$B$18="All",AU28='Dash 2'!$B$18)),1,0) -> 1
A29: 5061 | B29: 67 | C29: 0 | D29: 3 | E29: 2 | F29: 28.26 | G29: 1 | H29: 6.12 | I29: 6.25 | J29: 7.3 | K29: 5.15 | L29: 5.46 | M29: 2.77 | N29: 0 | O29: 0 | P29: 0 | Q29: 1 | R29: 0 | S29: 0 | T29: 2.7 | U29: 3.25 | V29: 1 | W29: 0 | X29: 1 | Y29: 1 | Z29: 1 | AA29: 1 | AB29: 1 | AC29: Male | AD29: Other | AE29: Bachelor's | AF29: Yes | AG29: No | AH29: No | AI29: No | AJ29: Yes | AK29: No | AL29: No | AM29: Yes | AN29: No | AO29: Yes | AP29: Yes | AQ29: Yes | AR29: Yes | AS29: Positive | AT29: 60+ | AU29: Overweight | AV29: 0.83 | AW29: 5 | AX29: 1 | AY29: =IF(AND(OR(Overview!$B$10="All",AC29=Overview!$B$10),OR(Overview!$B$12="All",AD29=Overview!$B$12),OR(Overview!$B$14="All",AF29=Overview!$B$14),OR(Overview!$B$16="All",AT29=Overview!$B$16),OR(Overview!$B$18="All",AU29=Overview!$B$18)),1,0) -> 1 | AZ29: =IF(AND(OR('Dash 1'!$B$10="All",AC29='Dash 1'!$B$10),OR('Dash 1'!$B$12="All",AD29='Dash 1'!$B$12),OR('Dash 1'!$B$14="All",AF29='Dash 1'!$B$14),OR('Dash 1'!$B$16="All",AT29='Dash 1'!$B$16),OR('Dash 1'!$B$18="All",AU29='Dash 1'!$B$18)),1,0) -> 1 | BA29: =IF(AND(OR('Dash 2'!$B$10="All",AC29='Dash 2'!$B$10),OR('Dash 2'!$B$12="All",AD29='Dash 2'!$B$12),OR('Dash 2'!$B$14="All",AF29='Dash 2'!$B$14),OR('Dash 2'!$B$16="All",AT29='Dash 2'!$B$16),OR('Dash 2'!$B$18="All",AU29='Dash 2'!$B$18)),1,0) -> 1
A30: 5062 | B30: 46 | C30: 0 | D30: 0 | E30: 2 | F30: 30.35 | G30: 0 | H30: 3.65 | I30: 5.02 | J30: 6.45 | K30: 6.08 | L30: 5.54 | M30: 5.92 | N30: 0 | O30: 0 | P30: 1 | Q30: 0 | R30: 0 | S30: 0 | T30: 2.99 | U30: 3.75 | V30: 0 | W30: 0 | X30: 1 | Y30: 1 | Z30: 1 | AA30: 1 | AB30: 0 | AC30: Male | AD30: Caucasian | AE30: Bachelor's | AF30: No | AG30: No | AH30: No | AI30: Yes | AJ30: No | AK30: No | AL30: No | AM30: No | AN30: No | AO30: Yes | AP30: Yes | AQ30: Yes | AR30: Yes | AS30: Negative | AT30: 45-59 | AU30: Obese | AV30: 0.8 | AW30: 4 | AX30: 1 | AY30: =IF(AND(OR(Overview!$B$10="All",AC30=Overview!$B$10),OR(Overview!$B$12="All",AD30=Overview!$B$12),OR(Overview!$B$14="All",AF30=Overview!$B$14),OR(Overview!$B$16="All",AT30=Overview!$B$16),OR(Overview!$B$18="All",AU30=Overview!$B$18)),1,0) -> 1 | AZ30: =IF(AND(OR('Dash 1'!$B$10="All",AC30='Dash 1'!$B$10),OR('Dash 1'!$B$12="All",AD30='Dash 1'!$B$12),OR('Dash 1'!$B$14="All",AF30='Dash 1'!$B$14),OR('Dash 1'!$B$16="All",AT30='Dash 1'!$B$16),OR('Dash 1'!$B$18="All",AU30='Dash 1'!$B$18)),1,0) -> 1 | BA30: =IF(AND(OR('Dash 2'!$B$10="All",AC30='Dash 2'!$B$10),OR('Dash 2'!$B$12="All",AD30='Dash 2'!$B$12),OR('Dash 2'!$B$14="All",AF30='Dash 2'!$B$14),OR('Dash 2'!$B$16="All",AT30='Dash 2'!$B$16),OR('Dash 2'!$B$18="All",AU30='Dash 2'!$B$18)),1,0) -> 1
A31: 5063 | B31: 38 | C31: 1 | D31: 0 | E31: 3 | F31: 28.7 | G31: 0 | H31: 3.73 | I31: 4.62 | J31: 8.09 | K31: 2.38 | L31: 6.62 | M31: 6.45 | N31: 0 | O31: 0 | P31: 1 | Q31: 0 | R31: 0 | S31: 0 | T31: 2.91 | U31: 3.36 | V31: 0 | W31: 0 | X31: 0 | Y31: 0 | Z31: 0 | AA31: 0 | AB31: 0 | AC31: Female | AD31: Caucasian | AE31: Higher | AF31: No | AG31: No | AH31: No | AI31: Yes | AJ31: No | AK31: No | AL31: No | AM31: No | AN31: No | AO31: No | AP31: No | AQ31: No | AR31: No | AS31: Negative | AT31: 30-44 | AU31: Overweight | AV31: 0.87 | AW31: 0 | AX31: 1 | AY31: =IF(AND(OR(Overview!$B$10="All",AC31=Overview!$B$10),OR(Overview!$B$12="All",AD31=Overview!$B$12),OR(Overview!$B$14="All",AF31=Overview!$B$14),OR(Overview!$B$16="All",AT31=Overview!$B$16),OR(Overview!$B$18="All",AU31=Overview!$B$18)),1,0) -> 1 | AZ31: =IF(AND(OR('Dash 1'!$B$10="All",AC31='Dash 1'!$B$10),OR('Dash 1'!$B$12="All",AD31='Dash 1'!$B$12),OR('Dash 1'!$B$14="All",AF31='Dash 1'!$B$14),OR('Dash 1'!$B$16="All",AT31='Dash 1'!$B$16),OR('Dash 1'!$B$18="All",AU31='Dash 1'!$B$18)),1,0) -> 1 | BA31: =IF(AND(OR('Dash 2'!$B$10="All",AC31='Dash 2'!$B$10),OR('Dash 2'!$B$12="All",AD31='Dash 2'!$B$12),OR('Dash 2'!$B$14="All",AF31='Dash 2'!$B$14),OR('Dash 2'!$B$16="All",AT31='Dash 2'!$B$16),OR('Dash 2'!$B$18="All",AU31='Dash 2'!$B$18)),1,0) -> 1
A32: 5064 | B32: 39 | C32: 0 | D32: 2 | E32: 1 | F32: 27.37 | G32: 0 | H32: 3.14 | I32: 7.06 | J32: 5.76 | K32: 6.59 | L32: 6.34 | M32: 4.86 | N32: 1 | O32: 0 | P32: 1 | Q32: 1 | R32: 1 | S32: 0 | T32: 2.57 | U32: 3.2 | V32: 1 | W32: 0 | X32: 1 | Y32: 1 | Z32: 0 | AA32: 1 | AB32: 1 | AC32: Male | AD32: Asian | AE32: High School | AF32: No | AG32: Yes | AH32: No | AI32: Yes | AJ32: Yes | AK32: Yes | AL32: No | AM32: Yes | AN32: No | AO32: Yes | AP32: Yes | AQ32: No | AR32: Yes | AS32: Positive | AT32: 30-44 | AU32: Overweight | AV32: 0.8 | AW32: 4 | AX32: 3 | AY32: =IF(AND(OR(Overview!$B$10="All",AC32=Overview!$B$10),OR(Overview!$B$12="All",AD32=Overview!$B$12),OR(Overview!$B$14="All",AF32=Overview!$B$14),OR(Overview!$B$16="All",AT32=Overview!$B$16),OR(Overview!$B$18="All",AU32=Overview!$B$18)),1,0) -> 1 | AZ32: =IF(AND(OR('Dash 1'!$B$10="All",AC32='Dash 1'!$B$10),OR('Dash 1'!$B$12="All",AD32='Dash 1'!$B$12),OR('Dash 1'!$B$14="All",AF32='Dash 1'!$B$14),OR('Dash 1'!$B$16="All",AT32='Dash 1'!$B$16),OR('Dash 1'!$B$18="All",AU32='Dash 1'!$B$18)),1,0) -> 1 | BA32: =IF(AND(OR('Dash 2'!$B$10="All",AC32='Dash 2'!$B$10),OR('Dash 2'!$B$12="All",AD32='Dash 2'!$B$12),OR('Dash 2'!$B$14="All",AF32='Dash 2'!$B$14),OR('Dash 2'!$B$16="All",AT32='Dash 2'!$B$16),OR('Dash 2'!$B$18="All",AU32='Dash 2'!$B$18)),1,0) -> 1
A33: 5065 | B33: 22 | C33: 1 | D33: 0 | E33: 0 | F33: 26.54 | G33: 0 | H33: 2.5 | I33: 4.45 | J33: 7.14 | K33: 0.39 | L33: 8.56 | M33: 6.68 | N33: 0 | O33: 1 | P33: 1 | Q33: 1 | R33: 1 | S33: 0 | T33: 2.74 | U33: 3.99 | V33: 0 | W33: 1 | X33: 1 | Y33: 1 | Z33: 1 | AA33: 0 | AB33: 0 | AC33: Female | AD33: Caucasian | AF33: No | AG33: No | AH33: Yes | AI33: Yes | AJ33: Yes | AK33: Yes | AL33: No | AM33: No | AN33: Yes | AO33: Yes | AP33: Yes | AQ33: Yes | AR33: No | AS33: Negative | AT33: 18-29 | AU33: Overweight | AV33: 0.69 | AW33: 4 | AX33: 4 | AY33: =IF(AND(OR(Overview!$B$10="All",AC33=Overview!$B$10),OR(Overview!$B$12="All",AD33=Overview!$B$12),OR(Overview!$B$14="All",AF33=Overview!$B$14),OR(Overview!$B$16="All",AT33=Overview!$B$16),OR(Overview!$B$18="All",AU33=Overview!$B$18)),1,0) -> 1 | AZ33: =IF(AND(OR('Dash 1'!$B$10="All",AC33='Dash 1'!$B$10),OR('Dash 1'!$B$12="All",AD33='Dash 1'!$B$12),OR('Dash 1'!$B$14="All",AF33='Dash 1'!$B$14),OR('Dash 1'!$B$16="All",AT33='Dash 1'!$B$16),OR('Dash 1'!$B$18="All",AU33='Dash 1'!$B$18)),1,0) -> 1 | BA33: =IF(AND(OR('Dash 2'!$B$10="All",AC33='Dash 2'!$B$10),OR('Dash 2'!$B$12="All",AD33='Dash 2'!$B$12),OR('Dash 2'!$B$14="All",AF33='Dash 2'!$B$14),OR('Dash 2'!$B$16="All",AT33='Dash 2'!$B$16),OR('Dash 2'!$B$18="All",AU33='Dash 2'!$B$18)),1,0) -> 1
A34: 5066 | B34: 12 | C34: 0 | D34: 3 | E34: 1 | F34: 30.49 | G34: 0 | H34: 6.16 | I34: 8.14 | J34: 10 | K34: 3.33 | L34: 0 | M34: 5.82 | N34: 1 | O34: 0 | P34: 0 | Q34: 1 | R34: 1 | S34: 0 | T34: 2.48 | U34: 3.2 | V34: 0 | W34: 0 | X34: 0 | Y34: 0 | Z34: 0 | AA34: 0 | AB34: 0 | AC34: Male | AD34: Other | AE34: High School | AF34: No | AG34: Yes | AH34: No | AI34: No | AJ34: Yes | AK34: Yes | AL34: No | AM34: No | AN34: No | AO34: No | AP34: No | AQ34: No | AR34: No | AS34: Negative | AT34: 0-17 (Child) | AU34: Obese | AV34: 0.78 | AW34: 0 | AX34: 2 | AY34: =IF(AND(OR(Overview!$B$10="All",AC34=Overview!$B$10),OR(Overview!$B$12="All",AD34=Overview!$B$12),OR(Overview!$B$14="All",AF34=Overview!$B$14),OR(Overview!$B$16="All",AT34=Overview!$B$16),OR(Overview!$B$18="All",AU34=Overview!$B$18)),1,0) -> 1 | AZ34: =IF(AND(OR('Dash 1'!$B$10="All",AC34='Dash 1'!$B$10),OR('Dash 1'!$B$12="All",AD34='Dash 1'!$B$12),OR('Dash 1'!$B$14="All",AF34='Dash 1'!$B$14),OR('Dash 1'!$B$16="All",AT34='Dash 1'!$B$16),OR('Dash 1'!$B$18="All",AU34='Dash 1'!$B$18)),1,0) -> 1 | BA34: =IF(AND(OR('Dash 2'!$B$10="All",AC34='Dash 2'!$B$10),OR('Dash 2'!$B$12="All",AD34='Dash 2'!$B$12),OR('Dash 2'!$B$14="All",AF34='Dash 2'!$B$14),OR('Dash 2'!$B$16="All",AT34='Dash 2'!$B$16),OR('Dash 2'!$B$18="All",AU34='Dash 2'!$B$18)),1,0) -> 1
A35: 5067 | B35: 47 | C35: 1 | D35: 1 | E35: 2 | F35: 29.59 | G35: 0 | H35: 4.7 | I35: 3.36 | J35: 4 | K35: 1.09 | L35: 6.05 | M35: 2.82 | N35: 0 | O35: 1 | P35: 1 | Q35: 1 | R35: 0 | S35: 0 | T35: 2.49 | U35: 3.01 | V35: 1 | W35: 0 | X35: 0 | Y35: 0 | Z35: 0 | AA35: 0 | AB35: 1 | AC35: Female | AD35: African American | AE35: Bachelor's | AF35: No | AG35: No | AH35: Yes | AI35: Yes | AJ35: Yes | AK35: No | AL35: No | AM35: Yes | AN35: No | AO35: No | AP35: No | AQ35: No | AR35: No | AS35: Positive | AT35: 45-59 | AU35: Overweight | AV35: 0.83 | AW35: 1 | AX35: 3 | AY35: =IF(AND(OR(Overview!$B$10="All",AC35=Overview!$B$10),OR(Overview!$B$12="All",AD35=Overview!$B$12),OR(Overview!$B$14="All",AF35=Overview!$B$14),OR(Overview!$B$16="All",AT35=Overview!$B$16),OR(Overview!$B$18="All",AU35=Overview!$B$18)),1,0) -> 1 | AZ35: =IF(AND(OR('Dash 1'!$B$10="All",AC35='Dash 1'!$B$10),OR('Dash 1'!$B$12="All",AD35='Dash 1'!$B$12),OR('Dash 1'!$B$14="All",AF35='Dash 1'!$B$14),OR('Dash 1'!$B$16="All",AT35='Dash 1'!$B$16),OR('Dash 1'!$B$18="All",AU35='Dash 1'!$B$18)),1,0) -> 1 | BA35: =IF(AND(OR('Dash 2'!$B$10="All",AC35='Dash 2'!$B$10),OR('Dash 2'!$B$12="All",AD35='Dash 2'!$B$12),OR('Dash 2'!$B$14="All",AF35='Dash 2'!$B$14),OR('Dash 2'!$B$16="All",AT35='Dash 2'!$B$16),OR('Dash 2'!$B$18="All",AU35='Dash 2'!$B$18)),1,0) -> 1
A36: 5068 | B36: 72 | C36: 0 | D36: 0 | E36: 2 | F36: 27.32 | G36: 0 | H36: 5.12 | I36: 8.39 | J36: 7.3 | K36: 7.07 | L36: 6.22 | M36: 6.34 | N36: 0 | O36: 0 | P36: 1 | Q36: 0 | R36: 0 | S36: 0 | T36: 1.78 | U36: 2.34 | V36: 0 | W36: 0 | X36: 1 | Y36: 1 | Z36: 1 | AA36: 0 | AB36: 1 | AC36: Male | AD36: Caucasian | AE36: Bachelor's | AF36: No | AG36: No | AH36: No | AI36: Yes | AJ36: No | AK36: No | AL36: No | AM36: No | AN36: No | AO36: Yes | AP36: Yes | AQ36: Yes | AR36: No | AS36: Positive | AT36: 60+ | AU36: Overweight | AV36: 0.76 | AW36: 3 | AX36: 1 | AY36: =IF(AND(OR(Overview!$B$10="All",AC36=Overview!$B$10),OR(Overview!$B$12="All",AD36=Overview!$B$12),OR(Overview!$B$14="All",AF36=Overview!$B$14),OR(Overview!$B$16="All",AT36=Overview!$B$16),OR(Overview!$B$18="All",AU36=Overview!$B$18)),1,0) -> 1 | AZ36: =IF(AND(OR('Dash 1'!$B$10="All",AC36='Dash 1'!$B$10),OR('Dash 1'!$B$12="All",AD36='Dash 1'!$B$12),OR('Dash 1'!$B$14="All",AF36='Dash 1'!$B$14),OR('Dash 1'!$B$16="All",AT36='Dash 1'!$B$16),OR('Dash 1'!$B$18="All",AU36='Dash 1'!$B$18)),1,0) -> 1 | BA36: =IF(AND(OR('Dash 2'!$B$10="All",AC36='Dash 2'!$B$10),OR('Dash 2'!$B$12="All",AD36='Dash 2'!$B$12),OR('Dash 2'!$B$14="All",AF36='Dash 2'!$B$14),OR('Dash 2'!$B$16="All",AT36='Dash 2'!$B$16),OR('Dash 2'!$B$18="All",AU36='Dash 2'!$B$18)),1,0) -> 1
A37: 5069 | B37: 9 | C37: 0 | D37: 1 | E37: 2 | F37: 22.53 | G37: 0 | H37: 7.8 | I37: 6.86 | J37: 7.35 | K37: 6 | L37: 4.41 | M37: 3.64 | N37: 0 | O37: 0 | P37: 0 | Q37: 1 | R37: 0 | S37: 0 | T37: 2.21 | U37: 2.59 | V37: 0 | W37: 0 | X37: 0 | Y37: 1 | Z37: 1 | AA37: 0 | AB37: 0 | AC37: Male | AD37: African American | AE37: Bachelor's | AF37: No | AG37: No | AH37: No | AI37: No | AJ37: Yes | AK37: No | AL37: No | AM37: No | AN37: No | AO37: No | AP37: Yes | AQ37: Yes | AR37: No | AS37: Negative | AT37: 0-17 (Child) | AU37: Normal | AV37: 0.86 | AW37: 2 | AX37: 1 | AY37: =IF(AND(OR(Overview!$B$10="All",AC37=Overview!$B$10),OR(Overview!$B$12="All",AD37=Overview!$B$12),OR(Overview!$B$14="All",AF37=Overview!$B$14),OR(Overview!$B$16="All",AT37=Overview!$B$16),OR(Overview!$B$18="All",AU37=Overview!$B$18)),1,0) -> 1 | AZ37: =IF(AND(OR('Dash 1'!$B$10="All",AC37='Dash 1'!$B$10),OR('Dash 1'!$B$12="All",AD37='Dash 1'!$B$12),OR('Dash 1'!$B$14="All",AF37='Dash 1'!$B$14),OR('Dash 1'!$B$16="All",AT37='Dash 1'!$B$16),OR('Dash 1'!$B$18="All",AU37='Dash 1'!$B$18)),1,0) -> 1 | BA37: =IF(AND(OR('Dash 2'!$B$10="All",AC37='Dash 2'!$B$10),OR('Dash 2'!$B$12="All",AD37='Dash 2'!$B$12),OR('Dash 2'!$B$14="All",AF37='Dash 2'!$B$14),OR('Dash 2'!$B$16="All",AT37='Dash 2'!$B$16),OR('Dash 2'!$B$18="All",AU37='Dash 2'!$B$18)),1,0) -> 1
A38: 5070 | B38: 70 | C38: 1 | D38: 1 | E38: 2 | F38: 27.93 | G38: 0 | H38: 7.93 | I38: 4 | J38: 6.7 | K38: 6.14 | L38: 0 | M38: 9.35 | N38: 0 | O38: 0 | P38: 0 | Q38: 0 | R38: 0 | S38: 0 | T38: 2.32 | U38: 2.98 | V38: 0 | W38: 0 | X38: 1 | Y38: 0 | Z38: 0 | AA38: 1 | AB38: 1 | AC38: Female | AD38: African American | AE38: Bachelor's | AF38: No | AG38: No | AH38: No | AI38: No | AJ38: No | AK38: No | AL38: No | AM38: No | AN38: No | AO38: Yes | AP38: No | AQ38: No | AR38: Yes | AS38: Positive | AT38: 60+ | AU38: Overweight | AV38: 0.78 | AW38: 2 | AX38: 0 | AY38: =IF(AND(OR(Overview!$B$10="All",AC38=Overview!$B$10),OR(Overview!$B$12="All",AD38=Overview!$B$12),OR(Overview!$B$14="All",AF38=Overview!$B$14),OR(Overview!$B$16="All",AT38=Overview!$B$16),OR(Overview!$B$18="All",AU38=Overview!$B$18)),1,0) -> 1 | AZ38: =IF(AND(OR('Dash 1'!$B$10="All",AC38='Dash 1'!$B$10),OR('Dash 1'!$B$12="All",AD38='Dash 1'!$B$12),OR('Dash 1'!$B$14="All",AF38='Dash 1'!$B$14),OR('Dash 1'!$B$16="All",AT38='Dash 1'!$B$16),OR('Dash 1'!$B$18="All",AU38='Dash 1'!$B$18)),1,0) -> 1 | BA38: =IF(AND(OR('Dash 2'!$B$10="All",AC38='Dash 2'!$B$10),OR('Dash 2'!$B$12="All",AD38='Dash 2'!$B$12),OR('Dash 2'!$B$14="All",AF38='Dash 2'!$B$14),OR('Dash 2'!$B$16="All",AT38='Dash 2'!$B$16),OR('Dash 2'!$B$18="All",AU38='Dash 2'!$B$18)),1,0) -> 1
A39: 5071 | B39: 67 | C39: 0 | D39: 2 | E39: 1 | F39: 25.66 | G39: 0 | H39: 1.38 | I39: 5.97 | J39: 6.73 | K39: 8.68 | L39: 4.85 | M39: 6.07 | N39: 1 | O39: 0 | P39: 0 | Q39: 0 | R39: 0 | S39: 0 | T39: 3.54 | U39: 4.14 | V39: 1 | W39: 0 | X39: 0 | Y39: 0 | Z39: 1 | AA39: 0 | AB39: 1 | AC39: Male | AD39: Asian | AE39: High School | AF39: No | AG39: Yes | AH39: No | AI39: No | AJ39: No | AK39: No | AL39: No | AM39: Yes | AN39: No | AO39: No | AP39: No | AQ39: Yes | AR39: No | AS39: Positive | AT39: 60+ | AU39: Overweight | AV39: 0.86 | AW39: 2 | AX39: 0 | AY39: =IF(AND(OR(Overview!$B$10="All",AC39=Overview!$B$10),OR(Overview!$B$12="All",AD39=Overview!$B$12),OR(Overview!$B$14="All",AF39=Overview!$B$14),OR(Overview!$B$16="All",AT39=Overview!$B$16),OR(Overview!$B$18="All",AU39=Overview!$B$18)),1,0) -> 1 | AZ39: =IF(AND(OR('Dash 1'!$B$10="All",AC39='Dash 1'!$B$10),OR('Dash 1'!$B$12="All",AD39='Dash 1'!$B$12),OR('Dash 1'!$B$14="All",AF39='Dash 1'!$B$14),OR('Dash 1'!$B$16="All",AT39='Dash 1'!$B$16),OR('Dash 1'!$B$18="All",AU39='Dash 1'!$B$18)),1,0) -> 1 | BA39: =IF(AND(OR('Dash 2'!$B$10="All",AC39='Dash 2'!$B$10),OR('Dash 2'!$B$12="All",AD39='Dash 2'!$B$12),OR('Dash 2'!$B$14="All",AF39='Dash 2'!$B$14),OR('Dash 2'!$B$16="All",AT39='Dash 2'!$B$16),OR('Dash 2'!$B$18="All",AU39='Dash 2'!$B$18)),1,0) -> 1
A40: 5072 | B40: 26 | C40: 0 | D40: 2 | E40: 2 | F40: 25.46 | G40: 1 | H40: 5.23 | I40: 4.23 | J40: 6.72 | K40: 4.21 | L40: 3.22 | M40: 3.25 | N40: 0 | O40: 0 | P40: 0 | Q40: 0 | R40: 0 | S40: 0 | T40: 2.83 | U40: 3.38 | V40: 0 | W40: 0 | X40: 0 | Y40: 0 | Z40: 0 | AA40: 0 | AB40: 0 | AC40: Male | AD40: Asian | AE40: Bachelor's | AF40: Yes | AG40: No | AH40: No | AI40: No | AJ40: No | AK40: No | AL40: No | AM40: No | AN40: No | AO40: No | AP40: No | AQ40: No | AR40: No | AS40: Negative | AT40: 18-29 | AU40: Overweight | AV40: 0.84 | AW40: 0 | AX40: 0 | AY40: =IF(AND(OR(Overview!$B$10="All",AC40=Overview!$B$10),OR(Overview!$B$12="All",AD40=Overview!$B$12),OR(Overview!$B$14="All",AF40=Overview!$B$14),OR(Overview!$B$16="All",AT40=Overview!$B$16),OR(Overview!$B$18="All",AU40=Overview!$B$18)),1,0) -> 1 | AZ40: =IF(AND(OR('Dash 1'!$B$10="All",AC40='Dash 1'!$B$10),OR('Dash 1'!$B$12="All",AD40='Dash 1'!$B$12),OR('Dash 1'!$B$14="All",AF40='Dash 1'!$B$14),OR('Dash 1'!$B$16="All",AT40='Dash 1'!$B$16),OR('Dash 1'!$B$18="All",AU40='Dash 1'!$B$18)),1,0) -> 1 | BA40: =IF(AND(OR('Dash 2'!$B$10="All",AC40='Dash 2'!$B$10),OR('Dash 2'!$B$12="All",AD40='Dash 2'!$B$12),OR('Dash 2'!$B$14="All",AF40='Dash 2'!$B$14),OR('Dash 2'!$B$16="All",AT40='Dash 2'!$B$16),OR('Dash 2'!$B$18="All",AU40='Dash 2'!$B$18)),1,0) -> 1
...

Sheet Calc
A1: KPI Summary — Overview (filtered) | F1: Diagnosis Rate by Smoking Status | L1: Symptom Prevalence (% of filtered patients)
A2: Total Patients | B2: =SUMPRODUCT(Data!$AY$2:$AY$2393) -> 2392 | F2: Category | G2: Total (filtered) | H2: Diagnosis Positive | I2: Diagnosis Rate | L2: Symptom | M2: Yes Count | N2: Total (filtered) | O2: Prevalence
A3: Diagnosis Positive Count | B3: =SUMPRODUCT((Data!$AY$2:$AY$2393=1)*(Data!$AB$2:$AB$2393=1)) -> 1171 | F3: Yes | G3: =SUMPRODUCT((Data!$AZ$2:$AZ$2393=1)*(Data!$AF$2:$AF$2393=F3)) -> 478 | H3: =SUMPRODUCT((Data!$AZ$2:$AZ$2393=1)*(Data!$AF$2:$AF$2393=F3)*(Data!$AB$2:$AB$2393=1)) -> 340 | I3: =IF(G3=0,0,H3/G3) -> 0.71129707 | L3: Wheezing | M3: =SUMPRODUCT((Data!$BA$2:$BA$2393=1)*(Data!$AM$2:$AM$2393="Yes")) -> 949 | N3: =SUMPRODUCT(Data!$BA$2:$BA$2393) -> 2392 | O3: =IF(N3=0,0,M3/N3) -> 0.39673913
A4: Diagnosis Rate | B4: =IF(B2=0,0,B3/B2) -> 0.48954849 | F4: No | G4: =SUMPRODUCT((Data!$AZ$2:$AZ$2393=1)*(Data!$AF$2:$AF$2393=F4)) -> 1914 | H4: =SUMPRODUCT((Data!$AZ$2:$AZ$2393=1)*(Data!$AF$2:$AF$2393=F4)*(Data!$AB$2:$AB$2393=1)) -> 831 | I4: =IF(G4=0,0,H4/G4) -> 0.43416928 | L4: Shortness of Breath | M4: =SUMPRODUCT((Data!$BA$2:$BA$2393=1)*(Data!$AN$2:$AN$2393="Yes")) -> 968 | N4: =SUMPRODUCT(Data!$BA$2:$BA$2393) -> 2392 | O4: =IF(N4=0,0,M4/N4) -> 0.40468227
A5: Avg BMI | B5: =IF(B2=0,0,SUMPRODUCT((Data!$AY$2:$AY$2393=1)*(Data!$F$2:$F$2393))/B2) -> 26.131961 | L5: Chest Tightness | M5: =SUMPRODUCT((Data!$BA$2:$BA$2393=1)*(Data!$AO$2:$AO$2393="Yes")) -> 841 | N5: =SUMPRODUCT(Data!$BA$2:$BA$2393) -> 2392 | O5: =IF(N5=0,0,M5/N5) -> 0.35158863
A6: Avg Symptom Count | B6: =IF(B2=0,0,SUMPRODUCT((Data!$AY$2:$AY$2393=1)*(Data!$AW$2:$AW$2393))/B2) -> 2.3858696 | F6: Diagnosis Rate by BMI Category | L6: Coughing | M6: =SUMPRODUCT((Data!$BA$2:$BA$2393=1)*(Data!$AP$2:$AP$2393="Yes")) -> 1112 | N6: =SUMPRODUCT(Data!$BA$2:$BA$2393) -> 2392 | O6: =IF(N6=0,0,M6/N6) -> 0.46488294
A7: Smoking Rate | B7: =IF(B2=0,0,SUMPRODUCT((Data!$AY$2:$AY$2393=1)*(Data!$G$2:$G$2393=1))/B2) -> 0.19983278 | F7: Category | G7: Total (filtered) | H7: Diagnosis Positive | I7: Diagnosis Rate | L7: Nighttime Symptoms | M7: =SUMPRODUCT((Data!$BA$2:$BA$2393=1)*(Data!$AQ$2:$AQ$2393="Yes")) -> 858 | N7: =SUMPRODUCT(Data!$BA$2:$BA$2393) -> 2392 | O7: =IF(N7=0,0,M7/N7) -> 0.35869565
F8: Underweight | G8: =SUMPRODUCT((Data!$AZ$2:$AZ$2393=1)*(Data!$AU$2:$AU$2393=F8)) -> 159 | H8: =SUMPRODUCT((Data!$AZ$2:$AZ$2393=1)*(Data!$AU$2:$AU$2393=F8)*(Data!$AB$2:$AB$2393=1)) -> 88 | I8: =IF(G8=0,0,H8/G8) -> 0.55345912 | L8: Exercise Induced | M8: =SUMPRODUCT((Data!$BA$2:$BA$2393=1)*(Data!$AR$2:$AR$2393="Yes")) -> 979 | N8: =SUMPRODUCT(Data!$BA$2:$BA$2393) -> 2392 | O8: =IF(N8=0,0,M8/N8) -> 0.40928094
A9: Diagnosis Rate by Gender | F9: Normal | G9: =SUMPRODUCT((Data!$AZ$2:$AZ$2393=1)*(Data!$AU$2:$AU$2393=F9)) -> 856 | H9: =SUMPRODUCT((Data!$AZ$2:$AZ$2393=1)*(Data!$AU$2:$AU$2393=F9)*(Data!$AB$2:$AB$2393=1)) -> 386 | I9: =IF(G9=0,0,H9/G9) -> 0.45093458
A10: Category | B10: Total (filtered) | C10: Diagnosis Positive | D10: Diagnosis Rate | F10: Overweight | G10: =SUMPRODUCT((Data!$AZ$2:$AZ$2393=1)*(Data!$AU$2:$AU$2393=F10)) -> 848 | H10: =SUMPRODUCT((Data!$AZ$2:$AZ$2393=1)*(Data!$AU$2:$AU$2393=F10)*(Data!$AB$2:$AB$2393=1)) -> 429 | I10: =IF(G10=0,0,H10/G10) -> 0.50589623
A11: Male | B11: =SUMPRODUCT((Data!$AY$2:$AY$2393=1)*(Data!$AC$2:$AC$2393=A11)) -> 1236 | C11: =SUMPRODUCT((Data!$AY$2:$AY$2393=1)*(Data!$AC$2:$AC$2393=A11)*(Data!$AB$2:$AB$2393=1)) -> 608 | D11: =IF(B11=0,0,C11/B11) -> 0.49190939 | F11: Obese | G11: =SUMPRODUCT((Data!$AZ$2:$AZ$2393=1)*(Data!$AU$2:$AU$2393=F11)) -> 529 | H11: =SUMPRODUCT((Data!$AZ$2:$AZ$2393=1)*(Data!$AU$2:$AU$2393=F11)*(Data!$AB$2:$AB$2393=1)) -> 268 | I11: =IF(G11=0,0,H11/G11) -> 0.50661626 | L11: Avg FEV1/FVC Ratio by Diagnosis
A12: Female | B12: =SUMPRODUCT((Data!$AY$2:$AY$2393=1)*(Data!$AC$2:$AC$2393=A12)) -> 1156 | C12: =SUMPRODUCT((Data!$AY$2:$AY$2393=1)*(Data!$AC$2:$AC$2393=A12)*(Data!$AB$2:$AB$2393=1)) -> 563 | D12: =IF(B12=0,0,C12/B12) -> 0.48702422 | L12: Diagnosis | M12: Total (filtered) | N12: Sum FEV1/FVC | O12: Avg FEV1/FVC Ratio
F13: Diagnosis Rate by Ethnicity | L13: Negative | M13: =SUMPRODUCT((Data!$BA$2:$BA$2393=1)*(Data!$AS$2:$AS$2393=L13)) -> 1221 | N13: =SUMPRODUCT((Data!$BA$2:$BA$2393=1)*(Data!$AS$2:$AS$2393=L13)*(Data!$AV$2:$AV$2393)) -> 980.16 | O13: =IF(M13=0,0,N13/M13) -> 0.80275184
A14: Diagnosis Rate by Age Group | F14: Category | G14: Total (filtered) | H14: Diagnosis Positive | I14: Diagnosis Rate | L14: Positive | M14: =SUMPRODUCT((Data!$BA$2:$BA$2393=1)*(Data!$AS$2:$AS$2393=L14)) -> 1171 | N14: =SUMPRODUCT((Data!$BA$2:$BA$2393=1)*(Data!$AS$2:$AS$2393=L14)*(Data!$AV$2:$AV$2393)) -> 914.11 | O14: =IF(M14=0,0,N14/M14) -> 0.7806234
A15: Category | B15: Total (filtered) | C15: Diagnosis Positive | D15: Diagnosis Rate | F15: Caucasian | G15: =SUMPRODUCT((Data!$AZ$2:$AZ$2393=1)*(Data!$AD$2:$AD$2393=F15)) -> 1334 | H15: =SUMPRODUCT((Data!$AZ$2:$AZ$2393=1)*(Data!$AD$2:$AD$2393=F15)*(Data!$AB$2:$AB$2393=1)) -> 650 | I15: =IF(G15=0,0,H15/G15) -> 0.48725637
A16: 0-17 (Child) | B16: =SUMPRODUCT((Data!$AY$2:$AY$2393=1)*(Data!$AT$2:$AT$2393=A16)) -> 426 | C16: =SUMPRODUCT((Data!$AY$2:$AY$2393=1)*(Data!$AT$2:$AT$2393=A16)*(Data!$AB$2:$AB$2393=1)) -> 220 | D16: =IF(B16=0,0,C16/B16) -> 0.51643192 | F16: African American | G16: =SUMPRODUCT((Data!$AZ$2:$AZ$2393=1)*(Data!$AD$2:$AD$2393=F16)) -> 478 | H16: =SUMPRODUCT((Data!$AZ$2:$AZ$2393=1)*(Data!$AD$2:$AD$2393=F16)*(Data!$AB$2:$AB$2393=1)) -> 227 | I16: =IF(G16=0,0,H16/G16) -> 0.4748954
A17: 18-29 | B17: =SUMPRODUCT((Data!$AY$2:$AY$2393=1)*(Data!$AT$2:$AT$2393=A17)) -> 372 | C17: =SUMPRODUCT((Data!$AY$2:$AY$2393=1)*(Data!$AT$2:$AT$2393=A17)*(Data!$AB$2:$AB$2393=1)) -> 174 | D17: =IF(B17=0,0,C17/B17) -> 0.46774194 | F17: Asian | G17: =SUMPRODUCT((Data!$AZ$2:$AZ$2393=1)*(Data!$AD$2:$AD$2393=F17)) -> 346 | H17: =SUMPRODUCT((Data!$AZ$2:$AZ$2393=1)*(Data!$AD$2:$AD$2393=F17)*(Data!$AB$2:$AB$2393=1)) -> 186 | I17: =IF(G17=0,0,H17/G17) -> 0.53757225 | L17: Patient Distribution by Ethnicity (filtered)
A18: 30-44 | B18: =SUMPRODUCT((Data!$AY$2:$AY$2393=1)*(Data!$AT$2:$AT$2393=A18)) -> 467 | C18: =SUMPRODUCT((Data!$AY$2:$AY$2393=1)*(Data!$AT$2:$AT$2393=A18)*(Data!$AB$2:$AB$2393=1)) -> 208 | D18: =IF(B18=0,0,C18/B18) -> 0.44539615 | F18: Other | G18: =SUMPRODUCT((Data!$AZ$2:$AZ$2393=1)*(Data!$AD$2:$AD$2393=F18)) -> 234 | H18: =SUMPRODUCT((Data!$AZ$2:$AZ$2393=1)*(Data!$AD$2:$AD$2393=F18)*(Data!$AB$2:$AB$2393=1)) -> 108 | I18: =IF(G18=0,0,H18/G18) -> 0.46153846 | L18: Ethnicity | M18: Total (filtered)
A19: 45-59 | B19: =SUMPRODUCT((Data!$AY$2:$AY$2393=1)*(Data!$AT$2:$AT$2393=A19)) -> 451 | C19: =SUMPRODUCT((Data!$AY$2:$AY$2393=1)*(Data!$AT$2:$AT$2393=A19)*(Data!$AB$2:$AB$2393=1)) -> 211 | D19: =IF(B19=0,0,C19/B19) -> 0.46784922 | L19: Caucasian | M19: =SUMPRODUCT((Data!$BA$2:$BA$2393=1)*(Data!$AD$2:$AD$2393=L19)) -> 1334
